"""
Database Connection Pool Failure Tests

Critical tests for database connection pool management to ensure system stability
under database failure conditions. These tests validate connection recovery,
pool exhaustion handling, and graceful degradation scenarios.
"""

import pytest
import asyncio
import time
from unittest.mock import AsyncMock, MagicMock, patch
from sqlalchemy.exc import DisconnectionError, OperationalError, InterfaceError
from contextlib import asynccontextmanager

from app.core.database import (
    create_engine, 
    create_session_factory, 
    init_database,
    get_session,
    get_database_url
)


class TestDatabaseConnectionPoolFailures:
    """Test suite for database connection pool failure scenarios."""

    @pytest.mark.asyncio
    async def test_connection_pool_exhaustion(self):
        """Test handling of connection pool exhaustion."""
        
        # Create a pool with very limited connections for testing
        with patch('app.core.database.create_async_engine') as mock_create_engine:
            mock_engine = AsyncMock()
            mock_create_engine.return_value = mock_engine
            
            # Simulate pool exhaustion
            mock_engine.begin.side_effect = OperationalError(
                "connection pool limit exceeded", None, None
            )
            
            with pytest.raises(OperationalError):
                async with get_session() as session:
                    pass
    
    @pytest.mark.asyncio
    async def test_database_unavailable_during_startup(self):
        """Test database initialization when database is unavailable."""
        
        with patch('app.core.database.create_async_engine') as mock_create_engine:
            mock_engine = AsyncMock()
            mock_create_engine.return_value = mock_engine
            
            # Simulate database unavailable
            mock_engine.begin.side_effect = OperationalError(
                "database server unavailable", None, None
            )
            
            with pytest.raises(OperationalError):
                await init_database()
    
    @pytest.mark.asyncio
    async def test_connection_leak_detection(self):
        """Test detection and cleanup of connection leaks."""
        
        with patch('app.core.database._engine') as mock_engine:
            mock_engine.pool.checked_in.return_value = 5
            mock_engine.pool.checked_out.return_value = 15
            mock_engine.pool.size.return_value = 20
            
            # Simulate connection leak scenario
            async with get_session() as session:
                # Session should automatically close even if not explicitly closed
                pass
            
            # Verify session was properly closed
            assert session.is_active is False
    
    @pytest.mark.asyncio
    async def test_transaction_rollback_under_failure(self):
        """Test transaction rollback when database operations fail."""
        
        with patch('app.core.database.get_session') as mock_get_session:
            mock_session = AsyncMock()
            mock_get_session.return_value.__aenter__.return_value = mock_session
            
            # Simulate transaction failure
            mock_session.execute.side_effect = OperationalError(
                "transaction rollback required", None, None
            )
            
            try:
                async with get_session() as session:
                    # This should trigger a rollback
                    await session.execute("SELECT 1")
                    await session.commit()
            except OperationalError:
                # Verify rollback was called
                mock_session.rollback.assert_called_once()
    
    @pytest.mark.asyncio
    async def test_connection_timeout_and_retry(self):
        """Test connection timeout handling and retry logic."""
        
        with patch('app.core.database.create_async_engine') as mock_create_engine:
            mock_engine = AsyncMock()
            mock_create_engine.return_value = mock_engine
            
            # First call times out, second succeeds
            mock_engine.begin.side_effect = [
                asyncio.TimeoutError("connection timeout"),
                AsyncMock()  # Success on retry
            ]
            
            # Should eventually succeed after retry
            async with get_session() as session:
                assert session is not None
    
    @pytest.mark.asyncio
    async def test_connection_recovery_after_database_restart(self):
        """Test connection recovery after database restart."""
        
        with patch('app.core.database._engine') as mock_engine:
            # Simulate database restart scenario
            mock_engine.begin.side_effect = [
                DisconnectionError("database connection lost", None, None),
                DisconnectionError("database connection lost", None, None),
                AsyncMock()  # Success after reconnection
            ]
            
            # Should recover after database comes back online
            async with get_session() as session:
                assert session is not None
    
    @pytest.mark.asyncio
    async def test_concurrent_connection_failures(self):
        """Test handling of concurrent connection failures."""
        
        with patch('app.core.database.get_session') as mock_get_session:
            mock_get_session.side_effect = OperationalError(
                "too many connections", None, None
            )
            
            # Multiple concurrent requests should all fail gracefully
            tasks = []
            for _ in range(10):
                task = asyncio.create_task(self._attempt_database_operation())
                tasks.append(task)
            
            results = await asyncio.gather(*tasks, return_exceptions=True)
            
            # All should fail with OperationalError
            assert all(isinstance(result, OperationalError) for result in results)
    
    async def _attempt_database_operation(self):
        """Helper method to attempt a database operation."""
        async with get_session() as session:
            return await session.execute("SELECT 1")


class TestDatabaseConnectionPoolRecovery:
    """Test suite for database connection pool recovery scenarios."""
    
    @pytest.mark.asyncio
    async def test_automatic_connection_pool_recovery(self):
        """Test automatic recovery of connection pool after failures."""
        
        recovery_attempts = 0
        
        async def mock_create_engine_with_recovery(*args, **kwargs):
            nonlocal recovery_attempts
            recovery_attempts += 1
            
            if recovery_attempts <= 2:
                raise OperationalError("database unavailable", None, None)
            else:
                # Success on third attempt
                return AsyncMock()
        
        with patch('app.core.database.create_async_engine', side_effect=mock_create_engine_with_recovery):
            # Should eventually succeed after retries
            engine = await create_engine()
            assert engine is not None
            assert recovery_attempts == 3
    
    @pytest.mark.asyncio
    async def test_connection_pool_health_monitoring(self):
        """Test connection pool health monitoring and reporting."""
        
        with patch('app.core.database._engine') as mock_engine:
            mock_engine.pool.size.return_value = 10
            mock_engine.pool.checked_in.return_value = 8
            mock_engine.pool.checked_out.return_value = 2
            mock_engine.pool.overflow.return_value = 0
            
            # Get pool status
            pool_status = {
                'size': mock_engine.pool.size(),
                'checked_in': mock_engine.pool.checked_in(),
                'checked_out': mock_engine.pool.checked_out(),
                'overflow': mock_engine.pool.overflow(),
                'health': 'healthy' if mock_engine.pool.checked_in() > 0 else 'critical'
            }
            
            assert pool_status['health'] == 'healthy'
            assert pool_status['checked_in'] + pool_status['checked_out'] == pool_status['size']
    
    @pytest.mark.asyncio
    async def test_graceful_degradation_on_database_failure(self):
        """Test graceful degradation when database is completely unavailable."""
        
        with patch('app.core.database.get_session') as mock_get_session:
            mock_get_session.side_effect = OperationalError(
                "database server not accessible", None, None
            )
            
            # System should handle database unavailability gracefully
            try:
                async with get_session() as session:
                    await session.execute("SELECT 1")
            except OperationalError as e:
                assert "database server not accessible" in str(e)
                # This is expected behavior - system should log error and continue
    
    @pytest.mark.asyncio
    async def test_connection_pool_configuration_validation(self):
        """Test validation of connection pool configuration."""
        
        # Test with invalid pool configuration
        with patch('app.core.config.settings') as mock_settings:
            mock_settings.DATABASE_POOL_SIZE = -1  # Invalid
            mock_settings.DATABASE_MAX_OVERFLOW = -1  # Invalid
            
            with pytest.raises(ValueError):
                await create_engine()


class TestDatabaseConnectionPerformance:
    """Test suite for database connection performance under stress."""
    
    @pytest.mark.asyncio
    async def test_connection_acquisition_performance(self):
        """Test connection acquisition performance under load."""
        
        start_time = time.time()
        
        # Simulate high-frequency connection requests
        tasks = []
        for _ in range(50):
            task = asyncio.create_task(self._quick_database_operation())
            tasks.append(task)
        
        await asyncio.gather(*tasks, return_exceptions=True)
        
        end_time = time.time()
        total_time = end_time - start_time
        
        # Should complete within reasonable time (adjust threshold as needed)
        assert total_time < 5.0, f"Connection acquisition took too long: {total_time}s"
    
    async def _quick_database_operation(self):
        """Helper method for quick database operation."""
        try:
            async with get_session() as session:
                # Simulate quick operation
                await asyncio.sleep(0.01)
                return True
        except Exception:
            return False
    
    @pytest.mark.asyncio
    async def test_connection_pool_stress_test(self):
        """Test connection pool under stress conditions."""
        
        success_count = 0
        failure_count = 0
        
        async def stress_operation():
            nonlocal success_count, failure_count
            try:
                async with get_session() as session:
                    await session.execute("SELECT 1")
                    success_count += 1
            except Exception:
                failure_count += 1
        
        # Create many concurrent operations
        tasks = [asyncio.create_task(stress_operation()) for _ in range(100)]
        await asyncio.gather(*tasks, return_exceptions=True)
        
        # Should have reasonable success rate
        total_operations = success_count + failure_count
        success_rate = success_count / total_operations if total_operations > 0 else 0
        
        assert success_rate > 0.8, f"Success rate too low: {success_rate}"


@pytest.mark.integration
class TestDatabaseIntegrationFailures:
    """Integration tests for database failure scenarios."""
    
    @pytest.mark.asyncio
    async def test_end_to_end_database_recovery(self):
        """Test end-to-end database recovery scenario."""
        
        # This would be an integration test with a real database
        # For now, we'll mock the scenario
        
        with patch('app.core.database.init_database') as mock_init:
            # Simulate database initialization failure followed by success
            mock_init.side_effect = [
                OperationalError("database not ready", None, None),
                None  # Success on retry
            ]
            
            # First attempt should fail
            with pytest.raises(OperationalError):
                await init_database()
            
            # Second attempt should succeed
            await init_database()
            mock_init.assert_called()